<?xml version='1.0'?>

<robot name="my_robot" xmlns:xacro="http://www.ros.org/wiki/xacro">
  <xacro:include filename="$(find my_robot)/urdf/my_robot.gazebo" />
  
  
  
  <link name="robot_footprint"></link>
	
<link name="left_wheel">
		<visual>
			<origin xyz="0 0 0" rpy="0 1.5707 1.5707"/>
			<geometry>
				<cylinder length = "0.05" radius = "0.1"/>
			</geometry>
			<material name="red">
			  <color rgba = "1 0 0 1"/>
			</material>
		</visual>
		
		<collision>
			<origin xyz="0 0 0" rpy="0 1.5707 1.5707"/>
			<geometry>
				<cylinder length = "0.05" radius = "0.1"/>
			</geometry>
			
		</collision>
	
		<inertial>
      <mass value="5.0"/>
      <origin xyz="0.0 0 0" rpy=" 0 1.5707 1.5707"/>
      <inertia
          ixx="0.1" ixy="0" ixz="0"
          iyy="0.1" iyz="0"
          izz="0.1"
      />
    </inertial>
	
	</link>
	
	<link name="right_wheel">
		<visual>
			<origin xyz="0 0 0" rpy="0 1.5707 1.5707"/>
			<geometry>
				<cylinder length = "0.05" radius = "0.1"/>
			</geometry>
			<material name="red">
			  <color rgba = "1 0 0 1"/>
			</material>
			
		</visual>
		
		<collision>
			<origin xyz="0 0 0" rpy="0 1.5707 1.5707"/>
			<geometry>
				<cylinder length = "0.05" radius = "0.1"/>
			</geometry>
			
		</collision>
	
		<inertial>
      <mass value="5.0"/>
      <origin xyz="0.0 0 0" rpy=" 0 1.5707 1.5707"/>
      <inertia
          ixx="0.1" ixy="0" ixz="0"
          iyy="0.1" iyz="0"
          izz="0.1"
      />
    </inertial>
	
	</link>
	
	<link name="camera_rgbd_frame"></link>
	
<joint name="camera_rgbd_joint" type="fixed">
<origin xyz="0 0 0" rpy="-${pi/2} 0 -${pi/2}"/>
<parent link="camera"/>
<child link="camera_rgbd_frame"/>
</joint>
	
	
	
	
	<link name="camera">
	  <visual>
	    <geometry>
	      <box size="0.05 0.05 0.05"/>
	    </geometry>
	     <origin xyz="0 0 0" rpy="0 0 0"/>
	     <material name="blue">
			  <color rgba = "0 0 1 1"/>
			</material>
	  </visual>
	  
	  <collision>
	  	<geometry>
	      <box size="0.05 0.05 0.05"/>
	    </geometry>
	    <origin xyz="0 0 0" rpy="0 0 0"/>
	  </collision>
	  
	  <inertial>
	    <origin xyz="0 0 0" rpy="0 0 0"/>
	    <mass value="0.1"/>
	    <inertia
          ixx="1e-6" ixy="0" ixz="0"
          iyy="1e-6" iyz="0"
          izz="1e-6"
      	/>
	  </inertial>
	  
	</link>
	
	  <joint name="camera_optical_joint" type="fixed">
    <origin xyz="0 0 0" rpy="-1.5707 0 -1.5707"/>
    <parent link="camera"/>
    <child link="camera_link_optical"/>
  </joint>

  <link name="camera_link_optical">
  </link>
	
	
	<link name="hokuyo">
	  <visual>
	    <origin xyz="0 0 0" rpy="0 0 0"/>
	    <geometry>
	      <mesh filename="package://my_robot/meshes/hokuyo.dae"/>
	    </geometry>
	  </visual>
	  
	  <collision>
	    <origin xyz="0 0 0" rpy="0 0 0"/>
	    <geometry>
	      <box size="0.1 0.1 0.1"/>
	     </geometry>
	  </collision>
	
	  <inertial>
	    <origin xyz="0 0 0" rpy="0 0 0"/>
	    <mass value="1e-5"/>
	    <inertia
          ixx="1e-6" ixy="0" ixz="0"
          iyy="1e-6" iyz="0"
          izz="1e-6"
      	/>
	  </inertial>
	
	
	</link>
	 
  <link name='chassis'>
    <pose>0 0 0.15 0 0 0</pose>

    <inertial>
      <mass value="15.0"/>
      <origin xyz="0.0 0 0" rpy=" 0 0 0"/>
      <inertia
          ixx="0.1" ixy="0" ixz="0"
          iyy="0.1" iyz="0"
          izz="0.1"
      />
    </inertial>

    <collision name='collision'>
      <origin xyz="0 0 0" rpy=" 0 0 0"/> 
      <geometry>
        <box size=".5 .3 .05"/>
      </geometry>
    </collision>

    <visual name='chassis_visual'>
      <origin xyz="0 0 0" rpy=" 0 0 0"/>
      <geometry>
        <box size=".5 .3 .05"/>
      </geometry>
      <material name="cyan">
			  <color rgba = "0 1 1 1"/>
			</material>
    </visual>


    <collision name='back_caster_collision'>
      <origin xyz="-0.15 0 -0.05" rpy=" 0 0 0"/>
      <geometry>
        <sphere radius="0.0499"/>
      </geometry>
    </collision>

    <visual name='back_caster_visual'>
      <origin xyz="-0.15 0 -0.05" rpy=" 0 0 0"/>
      <geometry>
        <sphere radius="0.05"/>
      </geometry>
    </visual>

    <collision name='front_caster_collision'>
      <origin xyz="0.15 0 -0.05" rpy=" 0 0 0"/>
      <geometry>
        <sphere radius="0.0499"/>
      </geometry>
    </collision>

    <visual name='front_caster_visual'>
      <origin xyz="0.15 0 -0.05" rpy=" 0 0 0"/>
      <geometry>
        <sphere radius="0.05"/>
      </geometry>
    </visual>

  </link>


  <joint type="continuous" name="left_wheel_hinge">
    <origin xyz="0 -0.175 0" rpy="0 0 0"/>
    <child link="left_wheel"/>
    <parent link="chassis"/>
    <axis xyz="0 1 0" rpy="0 0 0"/>
    <limit effort="10000" velocity="1000"/>
    <dynamics damping="1.0" friction="1.0"/>
  </joint>
	
	<joint type="continuous" name="right_wheel_hinge">
    <origin xyz="0 0.175 0" rpy="0 0 0"/>
    <child link="right_wheel"/>
    <parent link="chassis"/>
    <axis xyz="0 1 0" rpy="0 0 0"/>
    <limit effort="10000" velocity="1000"/>
    <dynamics damping="1.0" friction="1.0"/>
  </joint>
  
  <joint type="fixed" name="camera_joint">
    <origin xyz="0.275 0 0.015" rpy="0 0 0"/>
    <child link="camera"/>
    <parent link="chassis"/>
    <axis xyz="0 1 0"/>
  </joint>
  
  
  <joint type="fixed" name="hokuyo_joint">
    <origin xyz="0.15 0 0.05" rpy="0 0 0"/>
    <child link="hokuyo"/>
    <parent link="chassis"/>
    <axis xyz="0 1 0"/>
  </joint>
  
  
  <joint name="robot_footprint_joint" type="fixed">
    <origin xyz="0 0 0" rpy="0 0 0" />
    <parent link="robot_footprint"/>
    <child link="chassis" />
  </joint>


</robot>
